Workbook

Sheet INSTRUÇÕES
A1: VALIDAÇÃO DA FERRAMENTA TRI7 ALIA - QUALIFICAÇÃO REGISTRAL (ITN 004/2026-ONR)
A2: Controle de achados e sugestões ao desenvolvedor · Documento vivo para inserções diárias
A3: TÓPICO | B3: ORIENTAÇÃO
A4: FINALIDADE | B4: Registrar, de forma padronizada e rastreável, os achados dos testes da ferramenta na qualificação registral, com evidência, fundamento legal/normativo e sugestão ao desenvolvedor.
A5: ABAS | B5: REGISTRO DE ACHADOS (log diário) · EVIDÊNCIAS (imagens numeradas) · CHECKLIST ITN 004 (conformidade técnica) · CHECKLIST INTERFACE (usabilidade) · PAINEL (resumo automático) · LISTAS (valores permitidos).
A6: NOVO ACHADO | B6: Inserir na primeira linha livre da aba REGISTRO DE ACHADOS. Numeração sequencial: AC-030, AC-031... Nunca reutilizar ou renumerar IDs já enviados ao desenvolvedor.
A7: CAMPOS COM LISTA | B7: ETAPA / TELA, CATEGORIA, TIPO, CRITICIDADE, STATUS e RETESTE possuem lista suspensa. Para incluir valores, acrescentar na aba LISTAS.
A8: RELATO DO ANALISTA | B8: Transcrever o relato original, sem reescrever. Complementos técnicos vão em COMPORTAMENTO ESPERADO e FUNDAMENTO.
A9: EVIDÊNCIAS (OBRIGATÓRIO) | B9: Todo achado deve ter ao menos uma evidência. Numerar EV-027, EV-028... Na aba EVIDÊNCIAS: ID, achado vinculado, origem (arquivo e página/imagem), descrição e imagem colada na coluna IMAGEM. No Google Sheets: Inserir > Imagem > Imagem sobre as células.
A10: EVIDÊNCIAS ORIGINAIS | B10: Manter no Drive, na mesma pasta, o relatório original (.docx), as telas em PDF e a pasta de evidências numeradas, para preservação integral.
A11: CRITICIDADE | B11: ALTA: compromete a segurança jurídica (exigência indevida, óbice não apontado, erro de titularidade/especialidade). MÉDIA: exige conferência manual relevante. BAIXA: texto, layout ou conveniência.
A12: FLUXO DE STATUS | B12: ABERTO → ENVIADO AO DESENVOLVEDOR → EM CORREÇÃO → CORRIGIDO - AGUARDANDO RETESTE → VALIDADO (ou NÃO PROCEDE, com justificativa na coluna de resposta).
A13: REVISÃO COMPLEMENTAR | B13: Achados AC-022 a AC-029 foram identificados na revisão das telas (PDFs) e estão marcados como PENDENTE DE VALIDAÇÃO: confirmar antes de enviar ao desenvolvedor.
A14: FORMATAÇÃO | B14: Arial 10, centralizado, bordas em todas as linhas preenchidas. No Excel a borda é aplicada automaticamente ao preencher a coluna ID; no Google Sheets aplicar a borda manualmente (a formatação condicional do Sheets não suporta bordas).
... A16: CITAÇÕES | B16: Os fundamentos indicados devem ser conferidos pelo registrador antes do envio, especialmente dispositivos com redação alterada recentemente.

Sheet REGISTRO DE ACHADOS
A1: REGISTRO DE ACHADOS - VALIDAÇÃO TRI7 ALIA (QUALIFICAÇÃO REGISTRAL · ITN 004/2026-ONR)
A2: Clique no ID da evidência para abri-la na aba EVIDÊNCIAS
A3: ID | B3: DATA DO TESTE | C3: PROTOCOLO | D3: MATRÍCULA | E3: ANALISTA | F3: ETAPA / TELA | G3: CATEGORIA | H3: TIPO | I3: DESCRIÇÃO DO ACHADO (RELATO DO ANALISTA) | J3: COMPORTAMENTO ESPERADO | K3: FUNDAMENTO LEGAL / NORMATIVO | L3: EVIDÊNCIA | M3: SUGESTÃO AO DESENVOLVEDOR | N3: CRITICIDADE | O3: ACHADOS VINCULADOS | P3: STATUS | Q3: RESPOSTA DO DESENVOLVEDOR | R3: DATA DA RESPOSTA | S3: RETESTE
A4: AC-001 | B4: 28/09/2026 | C4: 185.989 | D4: 7.250 | E4: RAIANE FRANÇA CARDOSO | F4: 1 - TÍTULO (FÓLIO REGISTRAL) | G4: LEITURA DO FÓLIO | H4: ERRO DE LEITURA | I4: A leitura não apurou os proprietários atuais. | J4: Identificar os titulares atuais a partir da cadeia de atos da matrícula (cadastro Tri7 aponta: Alba Valéria de Mendonça Perfeito, Helenides Mendonça, José Mauro de Mendonça e Mauro Mendonça Junior). | K4: Lei 6.015/1973, art. 176, § 1º, II, 4; arts. 195 e 237 (continuidade). ITN 004/2026-ONR, Anexo VII (situação jurídica do imóvel). | L4: EV-01 | M4: Extrair titularidade de cada R./AV. e consolidar o quadro atual de titulares. Sem titulares apurados, bloquear a verificação de continuidade em vez de gerar exigência automática. | N4: ALTA | O4: AC-012; AC-029 | P4: ENVIADO AO DESENVOLVEDOR | S4: PENDENTE
A5: AC-002 | B5: 28/09/2026 | C5: 185.989 | D5: 7.250 | E5: RAIANE FRANÇA CARDOSO | F5: 1 - TÍTULO (INDICADOR REAL) | G5: LEITURA DO FÓLIO | H5: ERRO DE CLASSIFICAÇÃO | I5: A descrição foi alterada na AV.09 (Caracterização), porém a análise indica a AV.08 (Atualização de Designação Cadastral). | J5: Indicar a AV.09 (caracterização) como ato que alterou a descrição do imóvel; a AV.08 atualiza apenas a designação cadastral. | K5: Lei 6.015/1973, art. 176, § 1º, II, 3; art. 225. CNN (Prov. CNJ 149/2023), art. 440-AV. | L5: EV-02 | M5: Distinguir averbação de alteração cadastral (inscrição municipal) de averbação de descrição/caracterização (especialidade objetiva). | N5: ALTA | O5: AC-013 | P5: ABERTO | S5: PENDENTE
A6: AC-003 | B6: 28/09/2026 | C6: 185.989 | D6: 7.250 | E6: RAIANE FRANÇA CARDOSO | F6: 1 - TÍTULO (FÓLIO REGISTRAL) | G6: LEITURA DO FÓLIO | H6: ERRO DE CLASSIFICAÇÃO | I6: Identifica as AV.07, AV.09 e AV.10 como atos de compra e venda, porém elas são respectivamente averbações de código de endereçamento postal, caracterização e inserção de dados. | J6: AV.07: CEP (LNA 2.09.01.003 - Alteração de dados do logradouro). AV.09: caracterização (LNA 2.09.01.013 ou 2.09.01.999). AV.10: inserção de dados (código conforme o conteúdo; genérico 2.09.01.999 ou 2.08.01.999). | K6: ITN 004/2026-ONR, Anexo II (LNA-SREI). CNN, art. 440-AV, parágrafo único (averbação de CEP). | L6: EV-03 | M6: Classificar o ato pelo título/cabeçalho do ato (ex.: "CÓDIGO DE ENDEREÇAMENTO POSTAL") e não pelo título que o instrui (a escritura citada no corpo da AV.07). | N6: ALTA | O6: AC-011 | P6: ABERTO | S6: PENDENTE
A7: AC-004 | B7: 28/09/2026 | C7: 185.989 | D7: 7.250 | E7: RAIANE FRANÇA CARDOSO | F7: 1 - TÍTULO (CONFERÊNCIA COM O SISTEMA TRI7) | G7: LEITURA DO FÓLIO | H7: ERRO DE LEITURA | I7: Todas as informações abaixo estão no texto, porém só identificou elas no cadastro. (Titulares, tipo do imóvel, logradouro, número, CEP, lote, quadra e inscrição cadastral: 11 itens "só no cadastro".) | J7: Extrair do texto da matrícula os dados de titularidade e do indicador real e confrontá-los com o cadastro ("confere"/"diverge"). | K7: Lei 6.015/1973, art. 176, § 1º, II. ITN 004/2026-ONR, Anexo III (classes Pessoa e Imóvel). | L7: EV-04 | M7: Mapear os campos extraídos às classes de Pessoa e Imóvel do Anexo III da ITN 004 e só marcar "só no cadastro" após busca efetiva no texto. | N7: ALTA | O7: AC-001; AC-013 | P7: ABERTO | S7: PENDENTE
A8: AC-005 | B8: 28/09/2026 | C8: 185.989 | D8: 7.250 | E8: RAIANE FRANÇA CARDOSO | F8: 1 - TÍTULO (DECISÃO NECESSÁRIA) | G8: INTERFACE / USABILIDADE | H8: SUGESTÃO DE MELHORIA | I8: 1)- Vi que as decisões pendentes ficam especificadas no campo "exame", porém no campo da primeira imagem (EV-05), as informações são genéricas. Não seria mais viável se as decisões já viessem de forma detalhada no campo inicial? | J8: Cada decisão pendente identifica, já na etapa Título, o item do pedido a que se refere (Caracterização do Imóvel, Pacto Antenupcial, Inserção de Dados). | K8: Não se aplica (usabilidade). | L8: EV-05 | EV-06 | M8: Exibir em cada linha da "Decisão necessária" o nome do item lançado no pedido e as opções de código com nome do ato. | N8: MÉDIA | O8: AC-006; AC-009 | P8: ABERTO | S8: PENDENTE
A9: AC-006 | B9: 28/09/2026 | C9: 185.989 | D9: 7.250 | E9: RAIANE FRANÇA CARDOSO | F9: 1 - TÍTULO (DECISÃO NECESSÁRIA) | G9: NATUREZA DO ATO (LNA) | H9: DÚVIDA OPERACIONAL | I9: 2)- Na segunda decisão a análise diz que a natureza cabe em 2 atos da Lista Nacional, quais atos seriam esses? Só possui duas opções para confirmar, com códigos que não consigo identificar. | J9: 2.07.04.001 = Pacto antenupcial (Livro 2, notícia do registro do pacto na matrícula); 3.03.01.001 = Pacto antenupcial (Livro 3, registro auxiliar). Como o item foi lançado como "Pacto Antenupcial (Averbação)", o código aderente é 2.07.04.001. | K9: ITN 004/2026-ONR, Anexo II (LNA-SREI). Lei 6.015/1973, art. 167, II, 1 (averbação) e art. 178, V (registro no Livro 3). | L9: EV-05 | M9: Mostrar código + nome + livro de cada opção; usar o próprio lançamento ("Averbação") para pré-selecionar; permitir marcar os dois atos quando ambos forem praticados. Foi preciso pesquisar a ITN para localização. | N9: ALTA | O9: AC-005 | P9: ABERTO | S9: PENDENTE
A10: AC-007 | B10: 28/09/2026 | C10: 185.989 | D10: 7.250 | E10: RAIANE FRANÇA CARDOSO | F10: 2 - EXAME (DECISÕES PENDENTES) | G10: NATUREZA DO ATO (LNA) | H10: ERRO DE CLASSIFICAÇÃO | I10: 3)- No item da segunda imagem (EV-06), dispõe que os atos de caracterização do imóvel e inserção de dados não correspondem a nenhum ato da LNA, porém eu pratico esses dois atos no registro de imóveis. | J10: Correlacionar a nomenclatura interna da serventia à LNA; na ausência de código específico, usar o código genérico (ex.: 2.09.01.999 - Alteração de dados do imóvel, com nome complementar). | K10: ITN 004/2026-ONR, art. 2º e Anexo II (códigos genéricos "999" exigem nome complementar do ato). | L10: EV-06 | M10: Criar tabela de-para configurável (nome do ato na serventia/tabela de emolumentos-GO × código LNA). Nunca retornar "não corresponde" sem sugerir o código genérico. | N10: ALTA | O10: AC-008 | P10: ABERTO | S10: PENDENTE
A11: AC-008 | B11: 28/09/2026 | C11: 185.989 | D11: 7.250 | E11: RAIANE FRANÇA CARDOSO | F11: 2 - EXAME (DECISÕES PENDENTES) | G11: NATUREZA DO ATO (LNA) | H11: DÚVIDA OPERACIONAL | I11: Essa lista nacional de atos seria a lista disponibilizada no ITN 004 do ONR? São os mesmos atos que praticamos no registro? | J11: Sim: LNA-SREI instituída pelo art. 2º da ITN 004/2026 (Anexo II). Padroniza a terminologia nacional dos atos; a nomenclatura interna da serventia pode diferir e deve ser correlacionada. | K11: ITN 004/2026-ONR, art. 2º e parágrafo único; Anexo II. | L11: EV-06 | M11: Citar expressamente "LNA-SREI (Anexo II da ITN 004/2026-ONR)" e oferecer consulta ao ato (nome, descrição, livro, estrutura JSON) ao passar o cursor sobre o código. | N11: BAIXA | O11: AC-007 | P11: ABERTO | S11: PENDENTE
A12: AC-009 | B12: 28/09/2026 | C12: 185.989 | D12: 7.250 | E12: RAIANE FRANÇA CARDOSO | F12: 2 - EXAME (DECISÕES PENDENTES) | G12: INTERFACE / USABILIDADE | H12: INCONSISTÊNCIA DE INTERFACE | I12: Qual a diferença entre os campos de "confirmar o ato", "corrigir a natureza" e "tratar"? Pelo que identifiquei, são três opções que levam a mesma coisa. | J12: Cada botão executa ação distinta, com efeito descrito e registrado no histórico. | K12: Não se aplica (usabilidade). | L12: EV-06 | M12: Documentar/descrever o efeito de cada ação; unificar ações redundantes; manter rótulo único em todas as telas. | N12: MÉDIA | O12: AC-018 | P12: ABERTO | S12: PENDENTE
A13: AC-010 | B13: 28/09/2026 | C13: 185.989 | D13: 7.250 | E13: RAIANE FRANÇA CARDOSO | F13: 1 - TÍTULO (RESUMO DO PROTOCOLO) | G13: LEITURA DO TÍTULO / DOCUMENTOS | H13: ERRO DE LEITURA | I13: O protocolo possui 10 documentos no GED, 7 ficaram sem leitura. | J13: Ler e considerar todos os documentos do protocolo (inclusive consultas CNIB) ou justificar expressamente por que cada documento foi dispensado. | K13: Lei 6.015/1973, art. 198. CNN (Prov. CNJ 149/2023), arts. 320 a 320-J (CNIB). | L13: EV-07 | M13: Impedir a conclusão do exame com documentos não lidos sem justificativa; exibir o motivo da não leitura por documento. | N13: ALTA | O13: AC-022 | P13: ABERTO | S13: PENDENTE
A14: AC-011 | B14: 28/09/2026 | C14: 185.989 | D14: 7.250 | E14: RAIANE FRANÇA CARDOSO | F14: 1 - TÍTULO (ABRIR O FÓLIO) | G14: LEITURA DO FÓLIO | H14: ERRO DE CLASSIFICAÇÃO | I14: No campo de análise do protocolo, na visualização dos atos da matrícula (Abrir o fólio) as AV.07, AV.09 e AV.10 também ficaram cadastradas como compra e venda. | J14: Mesma classificação correta indicada no AC-003, refletida em todas as telas. | K14: ITN 004/2026-ONR, Anexo II (LNA-SREI). | L14: EV-08 | M14: Mesma correção do AC-003; garantir fonte única da classificação para todas as telas. | N14: ALTA | O14: AC-003 | P14: ABERTO | S14: PENDENTE
A15: AC-012 | B15: 28/09/2026 | C15: 185.989 | D15: 7.250 | E15: RAIANE FRANÇA CARDOSO | F15: 1 - TÍTULO (PONTOS NA LEITURA) | G15: LEITURA DO FÓLIO | H15: ERRO DE LEITURA | I15: O que significa "transferência sem pessoas extraídas"? Não conseguiu identificar quem são as partes do ato? (Tanto no cadastro, quanto no texto possuem adquirentes e transmitentes) | J15: Extrair transmitentes e adquirentes de cada ato de transmissão (R.15) e as pessoas da abertura (Ab.1). | K15: Lei 6.015/1973, art. 176, § 1º, III, 2. ITN 004/2026-ONR, Anexo V (estrutura genérica de transmissão). | L15: EV-09 | M15: Explicar a mensagem na tela; corrigir a extração de partes; não classificar AV.07/09/10 como transferência (AC-003). | N15: ALTA | O15: AC-001; AC-003 | P15: ABERTO | S15: PENDENTE
... A32: AC-029 | B32: 28/09/2026 | C32: 185.989 | D32: 7.250 | E32: RAFAIANE GONZAGA | F32: 3 - QUALIFICAÇÃO (NOTA DE EXIGÊNCIA) | G32: EXAME / EXIGÊNCIAS | H32: FALSO POSITIVO (EXIGÊNCIA INDEVIDA) | I32: Exigências nº 6 e nº 14 da nota ("Continuidade registral") são idênticas e decorrem da não apuração dos titulares atuais (AC-001). Evidência textual: Qualificação.pdf, p. 2-3. | J32: Verificação de continuidade somente após apuração dos titulares; exigência única, se cabível. | K32: Lei 6.015/1973, arts. 195, 198 e 237. | L32: EV-01 | M32: Condicionar a regra de continuidade à existência de titulares apurados; deduplicar. | N32: ALTA | O32: AC-001 | P32: ABERTO | S32: PENDENTE
A33: AC-030 | B33: 46295 | C33: SEM PROTOCOLO | D33: 39953 | E33: RAFAIANE GONZAGA | F33: LEITURA DA MATRÍCULA (PONTOS DE ATENÇÃO) | G33: INTERFACE / USABILIDADE | H33: SUGESTÃO DE MELHORIA | I33: Os pontos de atenção não deveriam ser apresentados ao usuário em linguagem simples e de fácil compreensão? Exemplo da escrita atual: "sequencia_nao_inicia_em_1: primeiro Av encontrado é o n. 3 - documento pode estar incompleto". | J33: Mensagem em linguagem natural, sem o identificador interno, por exemplo: "A primeira averbação localizada foi a AV.03. Confira se as averbações AV.01 e AV.02 foram lidas." Neste caso o alerta é também improcedente, pois a matrícula contém a AV.01 e a AV.02 (ver AC-042), de modo que a falha é da leitura, e não do documento. | K33: Não se aplica (usabilidade). | L33: EV-27 | M33: Criar catálogo de mensagens ao usuário, mantendo o código interno apenas em log técnico. Padronizar a grafia dos atos (AV.03, R.01) e não atribuir ao documento uma falha que pode ser do leitor. | N33: BAIXA | O33: AC-042 | P33: ABERTO | S33: PENDENTE
A34: AC-031 | B34: 46295 | C34: SEM PROTOCOLO | D34: 39953 | E34: RAFAIANE GONZAGA | F34: LEITURA DA MATRÍCULA (PONTOS DE ATENÇÃO) | G34: INTERFACE / USABILIDADE | H34: INCONSISTÊNCIA DE INTERFACE | I34: Por que foi escolhida a sigla "Ab.1" para tratar da abertura da matrícula? Isso não gera confusão, já que o primeiro ato após a abertura é numerado como 1, seja AV ou R? Nos próprios cadastros da Tri7, a matrícula é retratada como "Mat. 0". Na linha do tempo dos atos a ferramenta leu "Mat.0". Por que, então, ter "Ab.1"? | J34: Nomenclatura única para a abertura em todas as telas, compatível com o cadastro Tri7 ("Mat.0" ou "M-0"). A sigla "Ab.1" pode ser confundida com a AV.1 ou o R.1. | K34: Não se aplica (usabilidade). | L34: EV-27 | EV-32 | M34: Substituir "Ab.1" por "Mat.0" nos pontos de atenção e em todas as mensagens. A mesma sigla já aparecia na evidência do AC-012. | N34: MÉDIA | O34: AC-012 | P34: ABERTO | S34: PENDENTE
A35: AC-032 | B35: 46295 | C35: SEM PROTOCOLO | D35: 39953 | E35: RAFAIANE GONZAGA | F35: LEITURA DA MATRÍCULA (INDICADOR REAL) | G35: LEITURA DO FÓLIO | H35: ERRO DE LEITURA | I35: No indicador real consta "Fazenda Campo Limpo", enquanto no texto da matrícula consta "Fazenda Campo Limpo, Lugar Denominado São José e Tocantins". | J35: Denominação completa: "Fazenda Campo Limpo, Lugar Denominado São José e Tocantins", ou campos distintos para denominação e lugar denominado, correspondentes aos campos Nome e Característica do cadastro Tri7. | K35: Lei 6.015/1973, art. 176, § 1º, II, 3, a (imóvel rural: denominação e características). | L35: EV-29 | EV-34 | M35: Extrair o lugar denominado como elemento próprio da identificação do imóvel rural. | N35: MÉDIA | O35: AC-041 | P35: ABERTO | S35: PENDENTE
A36: AC-033 | B36: 46295 | C36: SEM PROTOCOLO | D36: 39953 | E36: RAFAIANE GONZAGA | F36: LEITURA DA MATRÍCULA (INDICADOR REAL) | G36: LEITURA DO FÓLIO | H36: ERRO DE LEITURA | I36: O código do INCRA não foi encontrado, mas no texto consta "código do imóvel rural: 936.120.021.091-9". | J36: Código INCRA (SNCR) preenchido com 936.120.021.091-9. A ferramenta extraiu o número do CCIR da mesma frase, o que indica falha no reconhecimento do rótulo "código do imóvel rural" como equivalente a código do imóvel no SNCR. | K36: Lei 6.015/1973, art. 176, § 1º, II, 3, a (código do imóvel e dados do CCIR). | L36: EV-29 | EV-35 | M36: Mapear os sinônimos do campo (código do imóvel rural, código INCRA, código SNCR) e validar o formato 000.000.000.000-0. | N36: ALTA | O36: AC-045 | P36: ABERTO | S36: PENDENTE
A37: AC-034 | B37: 46295 | C37: SEM PROTOCOLO | D37: 39953 | E37: RAFAIANE GONZAGA | F37: LEITURA DA MATRÍCULA (INDICADOR REAL) | G37: LEITURA DO FÓLIO | H37: ERRO DE LEITURA | I37: Não foram identificadas as benfeitorias, informação relevante. No texto consta: "Um sítio com casa sede de alvenaria coberta de telhas comuns, rego d'água, quintal fechado, um paiol de madeira roliça, com duas varandas, um chiqueiro cercado de madeira de lei com 25 metros quadrados e 3.000 metros de cercas de arame farpado com 4 fios e madeira de lei, e, Um sítio com casa de morada e casa de madeira roliça, ambas coberta de telhas, piso de cimento comum, dois currais com cerca de corrente e madeira, paiol em madeira roliça, coberto de telhas, rego d'água e outras benfeitorias existentes". | J37: Indicador real com campo de benfeitorias (ou características) contendo a descrição das benfeitorias constantes da abertura. | K37: Lei 6.015/1973, art. 176, § 1º, II, 3, a (características do imóvel). | L37: EV-29 | EV-34 | M37: Incluir o campo de benfeitorias no indicador real e na conferência com o cadastro Tri7. | N37: MÉDIA | O37: AC-045 | P37: ABERTO | S37: PENDENTE
A38: AC-035 | B38: 46295 | C38: SEM PROTOCOLO | D38: 39953 | E38: RAFAIANE GONZAGA | F38: LEITURA DA MATRÍCULA (INDICADOR REAL) | G38: LEITURA DO FÓLIO | H38: ERRO DE CLASSIFICAÇÃO | I38: O indicador real aponta reserva legal em "Mat.0" e "Av.3". Não há informação de reserva legal na abertura da matrícula, e a AV.03 é averbação do CAR, que contém dados de reserva legal, mas não é averbação de reserva legal. | J38: Reserva legal vinculada à AV.02 (transporte da AV.01 da matrícula 17.382, área de 22,6779 ha, termo de responsabilidade). Preservação florestal vinculada à AV.01 (transporte da AV.07 da matrícula 2.061, área de 11,40,00 ha, termo com o IBAMA). A área de reserva legal da AV.03 (31,761 ha) deve ser exibida como informação declaratória do CAR. | K38: Lei 6.015/1973, art. 167, II, 22. Lei 12.651/2012, arts. 18 e 29. ITN 004/2026-ONR, Anexo II: 2.10.04.024 (Reserva legal), 2.10.04.025 (Restrição ambiental) e 2.01.02.001 (Transporte). | L38: EV-29 | EV-37 | M38: Vincular cada selo ao ato que efetivamente constitui ou transporta a ocorrência. Distinguir ocorrência averbada de dado declaratório do CAR. | N38: ALTA | O38: AC-042; AC-043 | P38: ABERTO | S38: PENDENTE
A39: AC-036 | B39: 46295 | C39: SEM PROTOCOLO | D39: 39953 | E39: RAFAIANE GONZAGA | F39: LEITURA DA MATRÍCULA (INDICADOR REAL) | G39: LEITURA DO FÓLIO | H39: ERRO DE CLASSIFICAÇÃO | I39: O indicador real informa que foi alterado pela AV.03, mas o CAR não altera as informações do imóvel, pois é meramente declaratório. | J39: Campo "Alterado por" vazio, pois nenhum ato posterior alterou a descrição da abertura. O CAR tem natureza declaratória e não constitui título de propriedade ou posse, devendo figurar como informação ou ocorrência, e não como alteração do indicador real. | K39: Lei 12.651/2012, art. 29, caput e § 2º. | L39: EV-29 | EV-32 | M39: Não atribuir efeito de alteração do indicador real a averbações de CAR ou de transporte. Ver também o AC-044 quanto ao código LNA da AV.03. | N39: MÉDIA | O39: AC-044 | P39: ABERTO | S39: PENDENTE
A40: AC-037 | B40: 46295 | C40: SEM PROTOCOLO | D40: 39953 | E40: RAFAIANE GONZAGA | F40: LEITURA DA MATRÍCULA (PROPRIETÁRIO ATUAL) | G40: LEITURA DO FÓLIO | H40: ERRO DE LEITURA | I40: Não foi retornado o proprietário atual, embora no texto da matrícula conste: "João Alves da Silva, fazendeiro, portador da Carteira de Identidade RG n.º 789.900-SSP/GO, inscrito no CPF/MF sob o n.º 166.911.211-04, casado sob o regime da comunhão parcial de bens posteriormente ao advento da Lei Federal n.º 6.515/77, com Adegmar Cândida da Silva Alves, do lar, portadora da Carteira de Identidade RG n.º 644306-SSP/GO, inscrita no CPF/MF sob o n.º 192.900.201-72, brasileiros, residentes e domiciliados na Rua Turim, Quadra 09, Lote 02, Jardim Romano, Morrinhos-GO". É importante que sejam apresentados o nome completo do proprietário, o CPF e o estado civil e, se casado, o regime de bens, o nome completo do cônjuge e o respectivo CPF. | J40: Proprietário atual: João Alves da Silva, com CPF, casado no regime da comunhão parcial de bens posteriormente à Lei 6.515/1977 com Adegmar Cândida da Silva Alves, com o CPF da cônjuge (dados conforme EV-36). O ponto de atenção "abertura sem pessoas extraídas" também é improcedente. | K40: Lei 6.015/1973, art. 176, § 1º, II, 4, a. ITN 004/2026-ONR, Anexo VII (situação jurídica do imóvel). | L40: EV-30 | EV-27 | EV-36 | M40: Reincidência do AC-001. Exibir no card de proprietário, no mínimo: nome completo, CPF, estado civil e, se casado, regime de bens, nome completo e CPF do cônjuge. | N40: ALTA | O40: AC-001; AC-038 | P40: ABERTO | S40: PENDENTE
A41: AC-038 | B41: 46295 | C41: SEM PROTOCOLO | D41: 39953 | E41: RAFAIANE GONZAGA | F41: LEITURA DA MATRÍCULA (CONFERÊNCIA COM O SISTEMA TRI7) | G41: LEITURA DO FÓLIO | H41: ERRO DE LEITURA | I41: Na conferência com o sistema Tri7, o proprietário retornou apenas o nome conforme o cadastro, mas a informação consta no texto da matrícula. | J41: Coluna "Leitura do Atlas" preenchida com o titular extraído do texto e veredito "Confere", com a conferência estendida ao CPF, ao estado civil, ao regime de bens e ao cônjuge. | K41: Lei 6.015/1973, art. 176, § 1º, II, 4, a. ITN 004/2026-ONR, Anexo III (classe Pessoa). | L41: EV-31 | EV-36 | M41: Reincidência do AC-004. Só marcar "Só no cadastro" após busca efetiva no texto da abertura e dos atos posteriores. | N41: MÉDIA | O41: AC-004; AC-037 | P41: ABERTO | S41: PENDENTE
A42: AC-039 | B42: 46295 | C42: SEM PROTOCOLO | D42: 39953 | E42: RAFAIANE GONZAGA | F42: LEITURA DA MATRÍCULA (CONFERÊNCIA COM O SISTEMA TRI7) | G42: LEITURA DO FÓLIO | H42: ERRO DE CLASSIFICAÇÃO | I42: No imóvel rural, o logradouro está puxando o cadastro de qual campo do sistema? No cadastro Tri7 o campo apareceu em branco, mas há informações de localização, característica e complemento. Lembrando que o logradouro só existe para preenchimento nos imóveis urbanos. | J42: O campo Logradouro não possui correspondente no cadastro rural (por isso aparece em branco), e a leitura atribuiu a ele a expressão genérica "situada na zona rural deste município". Para imóvel rural, a conferência deve usar os campos Nome, Característica, Localização e Complemento dos Dados da Área Rural, comparando a localização com as indicações do CCIR ("Estrada Morrinhos Agua Limpa Km 24 a Direita" e, no cadastro, "Est Morrinhos Agua Limpa Km 24 A Dir"). | K42: Lei 6.015/1973, art. 176, § 1º, II, 3, a (rural: localização) e b (urbano: logradouro e número). | L42: EV-31 | EV-33 | EV-35 | M42: Adotar conjuntos de campos de conferência distintos para imóvel urbano e rural, conforme o tipo do imóvel. | N42: MÉDIA | O42: AC-041 | P42: ABERTO | S42: PENDENTE
A43: AC-040 | B43: 46295 | C43: SEM PROTOCOLO | D43: 39953 | E43: RAFAIANE GONZAGA | F43: LEITURA DA MATRÍCULA (CONFERÊNCIA COM O SISTEMA TRI7) | G43: LEITURA DO FÓLIO | H43: SUGESTÃO DE MELHORIA | I43: No sistema, a área só permite duas casas decimais após a vírgula, e deveria permitir, no mínimo, quatro. | J43: Área rural registrada em hectares com quatro casas decimais (hectares, ares e centiares), por exemplo 176,4743 ha. A conferência marcou "Confere" entre 176,47 (cadastro) e 176,4743 (leitura), o que oculta a diferença de precisão. | K43: Lei 6.015/1973, art. 176, § 1º, II, 3, a, e §§ 3º a 5º. Decreto 4.449/2002. | L43: EV-31 | EV-33 | M43: Ampliar o campo Área (m2/ha) do cadastro Tri7 para, no mínimo, quatro casas decimais. Na conferência, comparar com a mesma precisão e sinalizar divergência por arredondamento. | N43: MÉDIA | P43: ABERTO | S43: PENDENTE
A44: AC-041 | B44: 46295 | C44: SEM PROTOCOLO | D44: 39953 | E44: RAFAIANE GONZAGA | F44: LEITURA DA MATRÍCULA (CONFERÊNCIA COM O SISTEMA TRI7) | G44: LEITURA DO FÓLIO | H44: DÚVIDA OPERACIONAL | I44: A denominação não vai retornar também o lugar denominado? | J44: A conferência deve comparar "Lugar Denominado São José e Tocantins" com o campo Característica do cadastro Tri7 ("lugar denominado São José e Tocantins"), além da denominação. | K44: Lei 6.015/1973, art. 176, § 1º, II, 3, a. | L44: EV-31 | EV-33 | EV-34 | M44: Incluir a linha "Lugar denominado" na conferência do imóvel rural. | N44: BAIXA | O44: AC-032; AC-039 | P44: ABERTO | S44: PENDENTE
A45: AC-042 | B45: 46295 | C45: SEM PROTOCOLO | D45: 39953 | E45: RAFAIANE GONZAGA | F45: LEITURA DA MATRÍCULA (LINHA DO TEMPO DOS ATOS) | G45: LEITURA DO FÓLIO | H45: ERRO DE LEITURA | I45: Na linha do tempo dos atos, foram encontradas apenas a Mat.0 e a AV.3. No texto constam também "AV.01.39.953 - Data: 25.09.2026. TRASLADO/PRESERVAÇÃO FLORESTAL" e "AV.02.39.953 - Data: 25.09.2026. TRASLADO/RESERVA LEGAL". | J45: Ler o texto da matrícula na íntegra. | K45: Lei 6.015/1973, art. 176, § 1º, I. ITN 004/2026-ONR, Anexo VII. | L45: EV-32 | EV-28 | EV-37 | M45: Validar a sequência numérica antes de concluir que o documento está incompleto. | N45: ALTA | O45: AC-030; AC-035 | P45: ABERTO | S45: PENDENTE
A46: AC-043 | B46: 46295 | C46: SEM PROTOCOLO | D46: 39953 | E46: RAFAIANE GONZAGA | F46: LEITURA DA MATRÍCULA (LINHA DO TEMPO DOS ATOS) | G46: NATUREZA DO ATO (LNA) | H46: ERRO DE CLASSIFICAÇÃO | I46: A AV.03 foi classificada como "Alteração de cadastro do imóvel" (LNA 2.09.01.001), mas o ato é o traslado (transporte) da averbação do CAR existente nas matrículas de origem. A AV.01 e a AV.02, também de traslado, não foram classificadas. | J46: AV.01, AV.02 e AV.03 classificadas como Transporte (LNA 2.01.02.001), com indicação da ocorrência transportada: restrição ambiental (2.10.04.025), reserva legal (2.10.04.024) e informação do CAR. | K46: ITN 004/2026-ONR, Anexo II (LNA-SREI). | L46: EV-32 | EV-37 | M46: Reincidência do AC-003 (classificação pelo conteúdo e não pelo título do ato). Reconhecer o termo TRASLADO como transporte de ocorrência. | N46: MÉDIA | O46: AC-003; AC-036 | P46: ABERTO | S46: PENDENTE
A47: AC-044 | B47: 46295 | C47: SEM PROTOCOLO | D47: 39953 | E47: RAFAIANE GONZAGA | F47: LEITURA DA MATRÍCULA (INDICADOR REAL) | G47: LEITURA DO FÓLIO | H47: ERRO DE LEITURA | I47: O indicador real não apresenta o registro anterior (matrículas 2.061 e 17.382) nem a natureza da abertura (unificação decorrente de georreferenciamento). A informação consta da abertura e do cadastro Tri7 (aba Reg. Anterior). | J47: Indicar a origem (matrículas 2.061 e 17.382) e a causa da abertura (unificação, art. 213, II, da Lei 6.015/1973, e Decreto 4.449/2002), confrontando com a aba Reg. Anterior do cadastro. | K47: Lei 6.015/1973, art. 176, § 1º, II, 5, e art. 213, II. | L47: EV-29 | EV-33 | EV-36 | M47: Incluir o campo Registro anterior no indicador real e na conferência com o cadastro Tri7. | N47: MÉDIA | P47: ABERTO | S47: PENDENTE
A48: AC-045 | B48: 46295 | C48: SEM PROTOCOLO | D48: R.A. 29.555 | E48: RAIANE FRANÇA CARDOSO | F48: LEITURA DA MATRÍCULA (LINHA DO TEMPO DOS ATOS) | G48: LEITURA DO FÓLIO | H48: ERRO DE CLASSIFICAÇÃO | I48: A ferramenta não identifica o registro auxiliar e faz a análise como se fosse matrícula. | J48: Identificar o Livro 3 - Registro Auxiliar n.º 29.555. A tela exibe "Matrícula sem-numero-6af14c74" e "Livro 2", embora o texto se inicie com "Registro Auxiliar 29555". O ato inicial deve ser classificado como registro auxiliar de garantia (LNA 3.01.01.001 - Penhor, inclusive vinculado a cédulas, ou 3.01.01.002 - Alienação fiduciária de bem móvel, conforme a garantia), e não como 2.01.01.001 - Abertura de matrícula. | K48: Lei 6.015/1973, arts. 173 e 177. ITN 004/2026-ONR, Anexo II (atos do Livro 3). | L48: EV-40 | EV-43 | M48: Identificar o livro pelo cabeçalho do documento e pelo cadastro Tri7 antes da leitura e aplicar modelo de leitura próprio para o Livro 3. Extrair o número do registro auxiliar. | N48: ALTA | O48: AC-046; AC-047; AC-048 | P48: ABERTO | S48: PENDENTE
A49: AC-046 | B49: 46295 | C49: SEM PROTOCOLO | D49: R.A. 29.555 | E49: RAIANE FRANÇA CARDOSO | F49: LEITURA DA MATRÍCULA (PROPRIETÁRIO ATUAL) | G49: LEITURA DO FÓLIO | H49: ERRO DE CLASSIFICAÇÃO | I49: Em um registro auxiliar nunca haverá proprietário. Os vínculos mais comuns são: emitente/devedor, credor, fiel depositário, anuente, avalista, cônjuge, proprietário do imóvel de localização e representante. | J49: Substituir o card "Proprietário atual" por "Partes e vínculos". Neste registro: emitentes/devedores Nilo Cayro Vieira e Jaime Carlos Vieira, credora Cooperativa Mista dos Produtores de Leite de Morrinhos e, pela AV.01, proprietários dos imóveis de localização da lavoura. Os pontos de atenção "nenhum proprietário apurado" e "a leitura dos titulares atuais está incompleta" são improcedentes no Livro 3. | K49: Lei 6.015/1973, art. 177. Lei 8.929/1994, art. 3º. VERIFICAR REDAÇÃO VIGENTE. | L49: EV-38 | EV-42 | EV-43 | M49: Para o Livro 3, extrair as partes com o respectivo vínculo e não executar a apuração de titularidade. | N49: ALTA | O49: AC-037; AC-045 | P49: ABERTO | S49: PENDENTE
A50: AC-047 | B50: 46295 | C50: SEM PROTOCOLO | D50: R.A. 29.555 | E50: RAIANE FRANÇA CARDOSO | F50: LEITURA DA MATRÍCULA (INDICADOR REAL) | G50: LEITURA DO FÓLIO | H50: ERRO DE CLASSIFICAÇÃO | I50: Também não haverá descrição de endereço, por não se tratar de registro de imóvel. No registro auxiliar, os registros mais usuais são os relacionados a garantias, como penhor e alienação fiduciária, às escrituras de pacto antenupcial e de união estável, quando houver regime de bens diverso do legal, e à convenção de condomínio. | J50: No Livro 3, substituir o card "Indicador real" pelo objeto do registro (bem dado em garantia, pacto, convenção). | K50: Lei 6.015/1973, arts. 177 e 178. | L50: EV-39 | M50: Não aplicar a estrutura de indicador real a registro que não se refere a imóvel matriculado. | N50: MÉDIA | O50: AC-045; AC-048 | P50: ABERTO | S50: PENDENTE
A51: AC-048 | B51: 46295 | C51: SEM PROTOCOLO | D51: R.A. 29.555 | E51: RAIANE FRANÇA CARDOSO | F51: LEITURA DA MATRÍCULA (LINHA DO TEMPO DOS ATOS) | G51: LEITURA DO FÓLIO | H51: ERRO DE LEITURA | I51: Nos registros de garantias, a ferramenta deve: identificar as partes do ato, conforme os vínculos mencionados, identificar a garantia (penhor ou alienação fiduciária), identificar as características do bem dado em garantia (a descrição precisa ser completa e precisa), o valor da dívida, o vencimento e a forma de pagamento, a forma do título e o imóvel de localização do bem apenhado ou alienado e o local de formação da lavoura. | J51: Exibir os elementos da garantia. Neste registro, nenhum foi apresentado, embora o texto lido contenha, ao menos, as partes e a forma do título (Cédula de Produto Rural com Liquidação Financeira n.º 1061/2026, emitida em 29.07.2026). | K51: Lei 8.929/1994, arts. 3º e 4º-A. Lei 6.015/1973, art. 178. ITN 004/2026-ONR, Anexo II (3.01.01.001 e 3.01.01.002). | L51: EV-43 | EV-41 | M51: Criar quadro próprio para garantias: espécie, partes por vínculo, bem e características, valor, vencimento, forma de pagamento, forma do título, imóvel de localização e local de formação da lavoura. | N51: ALTA | O51: AC-045; AC-049 | P51: ABERTO | S51: PENDENTE
A52: AC-049 | B52: 46295 | C52: SEM PROTOCOLO | D52: R.A. 29.555 | E52: RAIANE FRANÇA CARDOSO | F52: LEITURA DA MATRÍCULA (LINHA DO TEMPO DOS ATOS) | G52: NATUREZA DO ATO (LNA) | H52: ERRO DE CLASSIFICAÇÃO | I52: Para obter essas informações, a ferramenta deve considerar todos os atos do registro auxiliar, e não somente o ato inicial. Por vezes, os aditivos averbados após o registro inicial alteram dados significativos, como a data de vencimento e a descrição do bem dado em garantia. | J52: A AV.01 ("ADITIVO") ficou "Não classificado", com efeito desconhecido. Ela deve ser classificada como alteração da garantia (LNA 3.01.03.001 - Alteração de penhor, 3.01.03.002 - Alteração de alienação fiduciária ou 3.01.03.999) e seus efeitos consolidados: inserção dos locais de formação da lavoura Fazenda Várzea ou Vera Cruz (matrícula 31.237) e Fazenda Vera Cruz (matrícula 36.404), com os respectivos proprietários. | K52: ITN 004/2026-ONR, Anexo II (3.01.03.001, 3.01.03.002 e 3.01.03.999). | L52: EV-44 | EV-40 | EV-41 | M52: Reconhecer ADITIVO como alteração da garantia e recompor a situação vigente do registro após cada averbação. | N52: ALTA | O52: AC-048 | P52: ABERTO | S52: PENDENTE
A53: AC-050 | B53: 46295 | C53: SEM PROTOCOLO | D53: R.A. 29.555 | E53: RAIANE FRANÇA CARDOSO | F53: LEITURA DA MATRÍCULA (PONTOS DE ATENÇÃO) | G53: INTERFACE / USABILIDADE | H53: INCONSISTÊNCIA DE INTERFACE | I53: Os pontos de atenção e o card "O que falta conferir" mantêm a sigla "Ab.1" e trazem redação inadequada: "A leitura de os titulares atuais está incompleta", "uma soma plausível não confirma o resultado" e "1 classificado". | J53: Redação revisada ("A leitura dos titulares atuais...", "1 classificado" no singular apenas quando aplicável) e sigla única "Mat.0" para o ato inicial. | K53: Não se aplica (usabilidade). | L53: EV-38 | EV-40 | EV-41 | M53: Reincidência do AC-031. Revisar o catálogo de mensagens, inclusive as do novo card "O que falta conferir". | N53: BAIXA | O53: AC-030; AC-031 | P53: ABERTO | S53: PENDENTE
A54: AC-051 | B54: 46295 | C54: SEM PROTOCOLO | D54: R.A. 29.555 | E54: REVISÃO COMPLEMENTAR (PENDENTE DE VALIDAÇÃO) | F54: LEITURA DA MATRÍCULA (ÔNUS E OCORRÊNCIAS) | G54: LEITURA DO FÓLIO | H54: ERRO DE CLASSIFICAÇÃO | I54: O card "Ônus e ocorrências vigentes" informa "Nenhum vigente. Fólio livre." em um registro auxiliar de cédula de produto rural, cujo próprio registro constitui a garantia. | J54: No Livro 3, não exibir "Fólio livre". Apresentar a garantia registrada e sua situação (vigente, alterada ou extinta). | K54: Lei 6.015/1973, art. 177. ITN 004/2026-ONR, Anexo II (3.01.01 a 3.01.03). | L54: EV-42 | M54: Adequar o card de ônus ao tipo de livro, exibindo, no Livro 3, a situação da garantia. | N54: MÉDIA | O54: AC-045; AC-048 | P54: ABERTO | S54: PENDENTE

Sheet EVIDÊNCIAS
A1: EVIDÊNCIAS
A2: ID EVIDÊNCIA | B2: ACHADO(S) VINCULADO(S) | C2: PROTOCOLO | D2: DESCRIÇÃO DO QUE A EVIDÊNCIA MOSTRA | E2: IMAGEM
A3: EV-01 | B3: AC-001; AC-029 | C3: 185.989 | D3: Card "Proprietário atual": nenhum apurado nesta leitura.
A4: EV-02 | B4: AC-002 | C4: 185.989 | D4: Indicador real após Av.16, área 1.210,67 m²; "Alterado por: Av.8".
A5: EV-03 | B5: AC-003 | C5: 185.989 | D5: Linha do tempo: Av.7, Av.9 e Av.10 como "Compra e venda / Transferência".
A6: EV-04 | B6: AC-004 | C6: 185.989 | D6: Conferência com o sistema Tri7: 2 conferem, 0 divergem, 11 só de um lado.
A7: EV-05 | B7: AC-005; AC-006 | C7: 185.989 | D7: Decisão necessária: "a natureza cabe em 2 atos da Lista Nacional" - Confirmar 2.07.04.001 / 3.03.01.001.
A8: EV-06 | B8: AC-005; AC-007; AC-008; AC-009 | C8: 185.989 | D8: Decisões pendentes: Caracterização e Inserção de Dados "não correspondem a nenhum ato da LNA"; botões Confirmar / Corrigir / Tratar.
A9: EV-07 | B9: AC-010 | C9: 185.989 | D9: Lidos 3 de 10 no protocolo; 7 documentos não lidos (CNIB).
A10: EV-08 | B10: AC-011 | C10: 185.989 | D10: Abrir o fólio: AV.07 (CEP) rotulada como "Compra e venda".
A11: EV-09 | B11: AC-012 | C11: 185.989 | D11: Pontos na leitura: Ab.1, Av.7, Av.9, Av.10 e R.15 "sem pessoas extraídas".
A12: EV-10 | B12: AC-013 | C12: 185.989 | D12: No fólio: descrição exibida é a da abertura da matrícula.
A13: EV-11 | B13: AC-014; AC-028 | C13: 185.989 | D13: Exigência "Preço, forma de pagamento e quitação" (art. 481 CC).
A14: EV-12 | B14: AC-015 | C14: 185.989 | D14: Exigência "Qualificação completa das partes" - observado: só folha de validação/manifesto.
... A28: EV-26 | B28: AC-024 | C28: 185.989 | D28: Exigência nº 13: "A leitura não encontrou ônus vigente no fólio — não há o que cancelar".
A29: EV-27 | B29: AC-030; AC-031; AC-037 | C29: SEM PROTOCOLO | D29: Pontos de atenção: "sequencia_nao_inicia_em_1", "nenhum proprietário apurado" e "abertura sem pessoas extraídas (Ab.1)". Origem: 1790776102511_image.png (enviado pela analista). | E29: #VALUE!
A30: EV-28 | B30: AC-042 | C30: SEM PROTOCOLO | D30: Cabeçalho: Matrícula 39953, lida em 30/09/2026, 2 atos, LNA 1.1. Origem: Analise_matrícula_39_953.pdf, p. 1.
A31: EV-29 | B31: AC-032; AC-033; AC-034; AC-035; AC-036; AC-043 | C31: SEM PROTOCOLO | D31: Indicador real: denominação sem lugar denominado, Código INCRA (SNCR) em branco, selos Reserva legal Mat.0 Av.3, alterado por Av.3. Origem: Analise_matrícula_39_953.pdf, p. 1.
A32: EV-30 | B32: AC-037; AC-043 | C32: SEM PROTOCOLO | D32: Proprietário atual: nenhum apurado. Ônus e ocorrências vigentes: nenhum vigente, fólio livre. Origem: Analise_matrícula_39_953.pdf, p. 1.
A33: EV-31 | B33: AC-038; AC-039; AC-040; AC-041 | C33: SEM PROTOCOLO | D33: Conferência com o sistema Tri7: titular só no cadastro, logradouro só na leitura, área 176.47 x 176,4743 com veredito Confere. Origem: Analise_matrícula_39_953.pdf, p. 1.
A34: EV-32 | B34: AC-031; AC-036; AC-042; AC-043 | C34: SEM PROTOCOLO | D34: Linha do tempo com apenas Mat.0 (lida a partir de trecho do perímetro) e Av.3 classificada como 2.09.01.001. Origem: Analise_matrícula_39_953.pdf, p. 2.
A35: EV-33 | B35: AC-031; AC-039; AC-040; AC-041; AC-044 | C35: SEM PROTOCOLO | D35: Cadastro Tri7 da matrícula 39.953: Dados da Área Rural, área com duas casas decimais, Reg. Anterior 2.061 e 17.382, Ônus conferido M-0, AV-1, AV-2, AV-3. Origem: 1790777192204_image.png (enviado pela analista).
A36: EV-34 | B36: AC-032; AC-034; AC-041 | C36: SEM PROTOCOLO | D36: Trecho da abertura com denominação completa e benfeitorias. Origem: Texto da matrícula n.º 39.953 (fornecido pela analista).
A37: EV-35 | B37: AC-033; AC-039 | C37: SEM PROTOCOLO | D37: Trecho da abertura com certificação INCRA, CCIR, código do imóvel rural 936.120.021.091-9, área e módulos. Origem: Texto da matrícula n.º 39.953 (fornecido pela analista).
A38: EV-36 | B38: AC-037; AC-038; AC-044 | C38: SEM PROTOCOLO | D38: Trecho da abertura com qualificação do proprietário e da cônjuge e origem (matrículas 2.061 e 17.382). Origem: Texto da matrícula n.º 39.953 (fornecido pela analista).
A39: EV-37 | B39: AC-035; AC-042; AC-043 | C39: SEM PROTOCOLO | D39: Cabeçalhos da AV.01, AV.02 e AV.03 (separadores ponto e hífen, datas de protocolo divergentes) e trechos das restrições. Origem: Texto da matrícula n.º 39.953 (fornecido pela analista).
A40: EV-38 | B40: AC-046; AC-050 | C40: SEM PROTOCOLO | D40: Pendência "A leitura de os titulares atuais está incompleta", que afeta a titularidade. Origem: Registro_Auxiliar_-_30_09_2026_-_Raiane.docx, imagem 1.
A41: EV-39 | B41: AC-047 | C41: SEM PROTOCOLO | D41: Indicador real "como está após Ab.1" com endereço no Distrito Agroindustrial de Morrinhos - DAIMO. Origem: Registro_Auxiliar_-_30_09_2026_-_Raiane.docx, imagem 2.
... A46: EV-44 | B46: AC-049 | C46: SEM PROTOCOLO | D46: Av.1 "Aditivo" não classificada: inserção dos locais de formação da lavoura (matrículas 31.237 e 36.404). Origem: Registro_Auxiliar_29_555.pdf, p. 2 (tela capturada em 01/10/2026 para validação do relatório).

Sheet CHECKLIST ITN 004
A1: CHECKLIST DE CONFORMIDADE - QUALIFICAÇÃO REGISTRAL E ITN 004/2026-ONR
A2: Repetir a verificação a cada nova versão da ferramenta
A3: ITEM | B3: PROTOCOLO / MATRÍCULA | C3: GRUPO | D3: REQUISITO VERIFICADO | E3: REFERÊNCIA NORMATIVA | F3: RESULTADO | G3: OBSERVAÇÃO (PROTOCOLO 185.989) | H3: ACHADOS VINCULADOS
A4: 1 | B4: 185.989 | C4: NATUREZA DO ATO (LNA) | D4: Utiliza os códigos da LNA-SREI para os atos pretendidos | E4: ITN 004, art. 2º; Anexo II | F4: ATENDE PARCIALMENTE | G4: Usa códigos, porém sem nome em parte das telas. | H4: AC-006
A5: 2 | B5: 185.989 | C5: NATUREZA DO ATO (LNA) | D5: Exibe código, nome do ato, livro e tema da LNA | E5: ITN 004, Anexo II | F5: ATENDE PARCIALMENTE | G5: Decisão necessária mostra só o código. | H5: AC-006
A6: 3 | B6: 185.989 | C6: NATUREZA DO ATO (LNA) | D6: Correlaciona a nomenclatura interna da serventia com a LNA, inclusive códigos genéricos "999" | E6: ITN 004, Anexo II | F6: NÃO ATENDE | G6: Caracterização e Inserção de Dados "não correspondem". | H6: AC-007
A7: 4 | B7: 185.989 | C7: NATUREZA DO ATO (LNA) | D7: Distingue ato de Livro 2 e de Livro 3 a partir do pedido | E7: ITN 004, Anexo II; Lei 6.015/1973, arts. 167, II, 1, e 178, V | F7: NÃO ATENDE | G7: Pacto lançado como "(Averbação)" e mantido em dúvida entre 2.07.04.001 e 3.03.01.001. | H7: AC-006
A8: 5 | B8: 185.989 | C8: NATUREZA DO ATO (LNA) | D8: Reconhece a quantidade exata de atos lançados no pedido | E8: ITN 004, Anexos II e X | F8: NÃO ATENDE | G8: 2 óbitos e 2 cancelamentos reduzidos a 1 de cada. | H8: AC-023
A9: 6 | B9: 185.989 | C9: LEITURA DO FÓLIO (ANEXO VII) | D9: Apura os titulares atuais do imóvel | E9: Lei 6.015/1973, art. 176, § 1º, II, 4; ITN 004, Anexo VII | F9: NÃO ATENDE | G9: Nenhum proprietário apurado. | H9: AC-001
A10: 7 | B10: 185.989 | C10: LEITURA DO FÓLIO (ANEXO VII) | D10: Classifica corretamente cada R./AV. da matrícula | E10: ITN 004, Anexo II | F10: NÃO ATENDE | G10: AV.07, AV.09 e AV.10 como compra e venda. | H10: AC-003; AC-011
A11: 8 | B11: 185.989 | C11: LEITURA DO FÓLIO (ANEXO VII) | D11: Compõe a descrição vigente após as averbações | E11: Lei 6.015/1973, arts. 176, § 1º, II, 3, e 225; CNN, art. 440-AV | F11: NÃO ATENDE | G11: Exibe descrição da abertura; aponta AV.08. | H11: AC-002; AC-013
A12: 9 | B12: 185.989 | C12: LEITURA DO FÓLIO (ANEXO VII) | D12: Extrai as partes de cada ato (abertura e transmissões) | E12: Lei 6.015/1973, art. 176, § 1º, III, 2 | F12: NÃO ATENDE | G12: "Sem pessoas extraídas" em Ab.1, R.15 e outros. | H12: AC-012
A13: 10 | B13: 185.989 | C13: LEITURA DO FÓLIO (ANEXO VII) | D13: Identifica ônus vigentes e extintos | E13: Lei 6.015/1973, arts. 248 a 251 | F13: VERIFICAR | G13: Declara fólio livre com pedido de cancelamento de hipoteca. | H13: AC-024
A14: 11 | B14: 185.989 | C14: LEITURA DO FÓLIO (ANEXO VII) | D14: Confronta cadastro × texto da matrícula | E14: ITN 004, Anexo III | F14: ATENDE PARCIALMENTE | G14: 11 itens "só no cadastro". | H14: AC-004
A15: 12 | B15: 185.989 | C15: TÍTULO E DOCUMENTOS | D15: Lê todos os documentos do protocolo (GED) | E15: Lei 6.015/1973, art. 198 | F15: NÃO ATENDE | G15: 3 de 10 lidos. | H15: AC-010
... A20: 17 | B20: 185.989 | C20: TÍTULO E DOCUMENTOS | D20: Extrai qualificação, estado civil e regime de bens das partes | E20: Lei 6.015/1973, art. 176, § 1º, III, 2 | F20: NÃO ATENDE | G20: Alerta contraria a própria evidência. | H20: AC-015; AC-020
A21: 18 | B21: 185.989 | C21: TÍTULO E DOCUMENTOS | D21: Verifica assinatura digital ICP-Brasil (cadeia, integridade, revogação) | E21: MP 2.200-2/2001; Lei 14.063/2020 | F21: ATENDE PARCIALMENTE | G21: Ressalva: cadeia não validada e sem CRL/OCSP.
A22: 19 | B22: 185.989 | C22: EXAME / EXIGÊNCIAS | D22: Exigências fundamentadas em dispositivo correto e vigente | E22: Lei 6.015/1973, art. 198 | F22: ATENDE PARCIALMENTE | G22: Denominação incorreta do CN-GO. | H22: AC-018; AC-028
A23: 20 | B23: 185.989 | C23: EXAME / EXIGÊNCIAS | D23: Exigências de uma só vez, articuladas, claras e sem duplicidade | E23: Lei 6.015/1973, art. 198 | F23: NÃO ATENDE | G23: 3 exigências idênticas de descrição; 2 de continuidade. | H23: AC-016; AC-029
A24: 21 | B24: 185.989 | C24: EXAME / EXIGÊNCIAS | D24: Cada exigência indica documento, página e trecho de origem | E24: Lei 6.015/1973, art. 198 | F24: NÃO ATENDE | G24: "Ver evidência" desabilitado ou só com assinatura. | H24: AC-017
A25: 22 | B25: 185.989 | C25: EXAME / EXIGÊNCIAS | D25: Não gera exigência sobre requisito comprovado no título | E25: Lei 6.015/1973, art. 198 | F25: NÃO ATENDE | G25: Preço, partes, descrição e alertas indevidos. | H25: AC-014; AC-015; AC-016; AC-020
A26: 23 | B26: 185.989 | C26: EXAME / EXIGÊNCIAS | D26: Registra no histórico as decisões e o responsável | E26: Boas práticas de rastreabilidade | F26: ATENDE | G26: Histórico com autor e horário das decisões.
A27: 24 | B27: 185.989 | C27: NOTA DE EXIGÊNCIA (ANEXO IX) | D27: Nome e versão do layout do documento | E27: ITN 004, Anexo IX (LayoutDocumento) | F27: NÃO VERIFICADO | G27: Não exibido na minuta. | H27: AC-027
A28: 25 | B28: 185.989 | C28: NOTA DE EXIGÊNCIA (ANEXO IX) | D28: Serventia: nome, CNS, oficial responsável e endereço | E28: ITN 004, Anexo IX (Serventia) | F28: NÃO ATENDE | G28: Ausentes na minuta. | H28: AC-027
A29: 26 | B29: 185.989 | C29: NOTA DE EXIGÊNCIA (ANEXO IX) | D29: Controle da solicitação: número e data do protocolo | E29: ITN 004, Anexo IX (ControleSolicitacao) | F29: ATENDE PARCIALMENTE | G29: Número presente; data do protocolo ausente. | H29: AC-027
A30: 27 | B30: 185.989 | C30: NOTA DE EXIGÊNCIA (ANEXO IX) | D30: Data e identificador da nota | E30: ITN 004, Anexo IX | F30: NÃO ATENDE | G30: Ausentes. | H30: AC-027
A31: 28 | B31: 185.989 | C31: NOTA DE EXIGÊNCIA (ANEXO IX) | D31: Exigências anteriores e protocolos relacionados | E31: ITN 004, Anexo IX | F31: NÃO VERIFICADO | G31: Campo não exibido. | H31: AC-027
A32: 29 | B32: 185.989 | C32: NOTA DE EXIGÊNCIA (ANEXO IX) | D32: Registros relacionados com CNM | E32: ITN 004, Anexo IX; Lei 6.015/1973, art. 235-A | F32: ATENDE PARCIALMENTE | G32: Matrícula 7250 sem CNM. | H32: AC-027
A33: 30 | B33: 185.989 | C33: NOTA DE EXIGÊNCIA (ANEXO IX) | D33: Requisitos com índice, assunto, descrição e fundamentação | E33: ITN 004, Anexo IX (RequisitoExigencia) | F33: ATENDE PARCIALMENTE | G33: Índice, descrição e fundamento presentes; assunto nem sempre. | H33: AC-027
A34: 31 | B34: 185.989 | C34: NOTA DE EXIGÊNCIA (ANEXO IX) | D34: Informações adicionais aderentes à lei (reingresso e prazo) | E34: Lei 6.015/1973, arts. 198 e 205 | F34: NÃO ATENDE | G34: Cláusula de "única remessa". | H34: AC-021
A35: 32 | B35: 185.989 | C35: NOTA DE EXIGÊNCIA (ANEXO IX) | D35: Responsável/signatário e assinatura eletrônica | E35: ITN 004, Anexo IX; Lei 6.015/1973, art. 198 | F35: NÃO ATENDE | G35: Emitida como "definitiva" sem assinatura. | H35: AC-026; AC-027
A36: 33 | B36: 185.989 | C36: NOTA DE EXIGÊNCIA (ANEXO IX) | D36: Exportação JSON validada pelo schema v1.1 | E36: ITN 004, Anexo IX (schema) | F36: NÃO VERIFICADO | G36: Só "Copiar texto" e "Baixar .docx". | H36: AC-027
A37: 34 | B37: 185.989 | C37: DEMAIS ANEXOS | D37: Anotação no Livro 1 e controle diário do protocolo | E37: ITN 004, Anexo IV | F37: NÃO VERIFICADO | G37: Não avaliado neste teste.
A38: 35 | B38: 185.989 | C38: DEMAIS ANEXOS | D38: Documento estruturado de ato no Livro 2 / Livro 3 | E38: ITN 004, Anexos V e VI | F38: NÃO VERIFICADO | G38: Não avaliado neste teste.
A39: 36 | B39: 185.989 | C39: DEMAIS ANEXOS | D39: Declaração de atos e recibo de custas e emolumentos | E39: ITN 004, Anexo X | F39: NÃO VERIFICADO | G39: Não avaliado neste teste. | H39: AC-023
A40: 37 | B40: 185.989 | C40: PROTEÇÃO DE DADOS | D40: Tratamento de dados pessoais (mascaramento, acesso) | E40: ITN 004, art. 5º; Lei 13.709/2018 | F40: VERIFICAR | G40: CPF mascarado em parte das telas e exibido por extenso no texto lido.
A41: 38 | B41: 39953 | C41: NATUREZA DO ATO (LNA) | D41: Utiliza os códigos da LNA-SREI para os atos da matrícula | E41: ITN 004, art. 2º, Anexo II | F41: ATENDE PARCIALMENTE | G41: Matrícula 39.953 (30/09/2026): usa códigos, mas classifica a AV.03 como 2.09.01.001 e não classifica a AV.01 e a AV.02. | H41: AC-043
A42: 39 | B42: 39953 | C42: NATUREZA DO ATO (LNA) | D42: Exibe código e nome do ato da LNA na linha do tempo | E42: ITN 004, Anexo II | F42: ATENDE | G42: Matrícula 39.953 (30/09/2026): Mat.0 com 2.01.01.001 (Abertura de matrícula) e Av.3 com 2.09.01.001 (Alteração de cadastro do imóvel).
A43: 40 | B43: 39953 | C43: NATUREZA DO ATO (LNA) | D43: Correlaciona a nomenclatura da serventia com a LNA | E43: ITN 004, Anexo II | F43: NÃO ATENDE | G43: Matrícula 39.953 (30/09/2026): o termo TRASLADO não foi reconhecido como Transporte (2.01.02.001). | H43: AC-043
A44: 41 | B44: 39953 | C44: LEITURA DO FÓLIO (ANEXO VII) | D44: Apura os titulares atuais do imóvel | E44: Lei 6.015/1973, art. 176, § 1º, II, 4, a. ITN 004, Anexo VII | F44: NÃO ATENDE | G44: Matrícula 39.953 (30/09/2026): nenhum proprietário apurado, embora qualificado na abertura. | H44: AC-037
...

Sheet CHECKLIST INTERFACE
A1: CHECKLIST DE INTERFACE E INTUITIVIDADE - TRI7 ALIA
A2: Avaliação heurística a partir das telas Título, Exame, Qualificação e Expediente
A3: ITEM | B3: CRITÉRIO AVALIADO | C3: TELA | D3: OBSERVAÇÃO | E3: RESULTADO | F3: SUGESTÃO | G3: EVIDÊNCIA
A4: 1 | B4: Fluxo em etapas (Título → Exame → Qualificação) | C4: Todas | D4: Sequência clara e visível no topo da tela. | E4: ATENDE | F4: Manter. | G4: EV-24
A5: 2 | B5: Visualização lado a lado (imagem × texto lido) | C5: Expediente | D5: Recurso adequado à conferência pela imagem. | E5: ATENDE | F5: Alertar quando o texto lido estiver vazio ou for só assinatura. | G5: EV-22
A6: 3 | B6: Ações com significado distinto e autoexplicativo | C6: Exame | D6: Confirmar / Corrigir / Tratar e Está em ordem / Gerar exigência / Tratar parecem equivalentes. | E6: NÃO ATENDE | F6: Tooltip e descrição do efeito; eliminar redundâncias. | G6: EV-06; EV-15
A7: 4 | B7: Consistência de contadores entre telas | C7: Exame / Qualificação | D7: A decidir 0 × Decisões 6; 17/41 × Do exame 8. | E7: NÃO ATENDE | F7: Fonte única e legenda. | G7: EV-23; EV-24; EV-25
A8: 5 | B8: Status do documento condizente com a etapa | C8: Qualificação | D8: "DEFINITIVA" antes da conclusão e sem assinatura. | E8: NÃO ATENDE | F8: Status de minuta até a assinatura. | G8: EV-25
A9: 6 | B9: Decisões pendentes identificam o item do pedido | C9: Título | D9: Mensagens genéricas repetidas. | E9: NÃO ATENDE | F9: Exibir nome do item lançado e do ato LNA. | G9: EV-05
A10: 7 | B10: Rastreabilidade ("Ver evidência") | C10: Exame | D10: Desabilitado ou restrito à assinatura. | E10: NÃO ATENDE | F10: Abrir documento, página e trecho. | G10: EV-14
A11: 8 | B11: Textos truncados em listas | C11: Exame | D11: Títulos e resumos cortados por reticências. | E11: ATENDE PARCIALMENTE | F11: Expandir ao passar o cursor ou quebrar linha. | G11: EV-24
A12: 9 | B12: Linguagem e nomenclatura | C12: Todas | D12: Atlas × Alia; termos "banca", "trava", "fora"; concordância. | E12: ATENDE PARCIALMENTE | F12: Glossário e revisão textual. | G12: EV-11; EV-15
A13: 10 | B13: Legenda de selos (Trava, Em ordem, Só no cadastro, Da banca) | C13: Exame / Título | D13: Sem legenda visível. | E13: ATENDE PARCIALMENTE | F13: Incluir legenda. | G13: EV-04; EV-15
A14: 11 | B14: Aviso de documentos não lidos | C14: Título | D14: Aviso existe, mas não impede a conclusão nem traz motivo. | E14: ATENDE PARCIALMENTE | F14: Exigir justificativa por documento. | G14: EV-07
A15: 12 | B15: Justificativa das decisões do usuário | C15: Exame | D15: Texto padrão atribuído ao usuário ("Conferido na conclusão..."). | E15: ATENDE PARCIALMENTE | F15: Permitir/exigir justificativa própria.
A16: 13 | B16: Acessibilidade (contraste, teclado, leitor de tela) | C16: Todas | D16: Não avaliado neste teste. | E16: NÃO VERIFICADO | F16: Avaliar em teste específico.
A17: 14 | B17: Desempenho e tempo de resposta | C17: Todas | D17: Não avaliado neste teste. | E17: NÃO VERIFICADO | F17: Registrar tempos nos próximos testes.
A18: 15 | B18: Pontos de atenção em linguagem natural, sem identificador interno | C18: Leitura da matrícula | D18: Matrícula 39.953 (30/09/2026): alerta exibido como sequencia_nao_inicia_em_1. | E18: NÃO ATENDE | F18: Catálogo de mensagens ao usuário. | G18: EV-27
A19: 16 | B19: Nomenclatura única para a abertura da matrícula | C19: Leitura da matrícula | D19: Matrícula 39.953 (30/09/2026): Ab.1 nos pontos de atenção e Mat.0 na linha do tempo. | E19: NÃO ATENDE | F19: Adotar Mat.0 em todas as telas. | G19: EV-27; EV-32
A20: 17 | B20: Campos de conferência adequados ao tipo do imóvel (urbano ou rural) | C20: Leitura da matrícula | D20: Matrícula 39.953 (30/09/2026): logradouro exibido para imóvel rural e sem os campos Característica e Localização. | E20: NÃO ATENDE | F20: Conjuntos de campos distintos por tipo de imóvel. | G20: EV-31; EV-33
A21: 18 | B21: Selos do indicador real vinculados ao ato correto | C21: Leitura da matrícula | D21: Matrícula 39.953 (30/09/2026): selo Reserva legal com Mat.0 e Av.3. | E21: NÃO ATENDE | F21: Vincular o selo ao ato que constitui ou transporta a ocorrência. | G21: EV-29
A22: 19 | B22: Veredito de conferência sensível à precisão numérica | C22: Leitura da matrícula | D22: Matrícula 39.953 (30/09/2026): 176.47 e 176,4743 com veredito Confere. | E22: NÃO ATENDE | F22: Sinalizar divergência por arredondamento. | G22: EV-31
A23: 20 | B23: Trecho de origem exibido condizente com o ato | C23: Leitura da matrícula | D23: Matrícula 39.953 (30/09/2026): abertura lida no documento como trecho intermediário do perímetro. | E23: NÃO ATENDE | F23: Exibir o início do ato e destacar o trecho usado. | G23: EV-32
A24: 21 | B24: Contagem e concordância na linha do tempo | C24: Leitura da matrícula | D24: Matrícula 39.953 (30/09/2026): cabeçalho com 2 atos e selo 2 classificado, quando a matrícula tem abertura e três averbações. | E24: ATENDE PARCIALMENTE | F24: Corrigir a contagem e a concordância (2 classificados). | G24: EV-28
A25: 22 | B25: Mensagens e cards adaptados ao tipo de livro | C25: Leitura do registro auxiliar | D25: Registro Auxiliar 29.555 (30/09/2026): cobra proprietário e exibe indicador real com endereço em registro do Livro 3. | E25: NÃO ATENDE | F25: Cards próprios para o Livro 3 (partes e vínculos, objeto e garantia). | G25: EV-38; EV-39
A26: 23 | B26: Identificação do livro e do número no cabeçalho | C26: Leitura do registro auxiliar | D26: Registro Auxiliar 29.555 (30/09/2026): cabeçalho "Matrícula sem-numero-6af14c74 · Livro 2". | E26: NÃO ATENDE | F26: Exibir "Registro Auxiliar n.º 29.555 · Livro 3". | G26: EV-40
A27: 24 | B27: Card "O que falta conferir" com pendências e atalho para o trecho | C27: Leitura do registro auxiliar | D27: Registro Auxiliar 29.555 (30/09/2026): recurso novo e útil, com atalho "Conferir trecho de Av.1", mas com linguagem técnica e erro de concordância. | E27: ATENDE PARCIALMENTE | F27: Manter o recurso e revisar a redação. | G27: EV-41
A28: 25 | B28: Nomenclatura única para o ato inicial | C28: Leitura do registro auxiliar | D28: Registro Auxiliar 29.555 (30/09/2026): "Ab.1" nos pontos de atenção e "Mat.0" na linha do tempo. | E28: NÃO ATENDE | F28: Reincidência do item 16. Adotar sigla única. | G28: EV-40; EV-43
A29: 26 | B29: Impressão da tela sem sobreposição de elementos | C29: Leitura do registro auxiliar | D29: Registro Auxiliar 29.555 (30/09/2026): a barra superior encobre o texto do card de ônus na impressão. | E29: NÃO ATENDE | F29: Ajustar a folha de estilo de impressão. | G29: EV-42

Sheet PAINEL
A1: PAINEL DE ACOMPANHAMENTO
A2: Contagens automáticas (atualizam conforme novas linhas são inseridas)
A3: INDICADOR | B3: VALOR | C3: OBSERVAÇÃO
A4: TOTAL DE ACHADOS REGISTRADOS | B4: =COUNTIF('REGISTRO DE ACHADOS'!$A$4:$A$1000,"AC-*") -> 51 | C4: Conta os IDs iniciados por AC-
A5: CRITICIDADE ALTA | B5: =COUNTIF('REGISTRO DE ACHADOS'!$N$4:$N$1000,"ALTA") -> 30
A6: CRITICIDADE MÉDIA | B6: =COUNTIF('REGISTRO DE ACHADOS'!$N$4:$N$1000,"MÉDIA") -> 16
A7: CRITICIDADE BAIXA | B7: =COUNTIF('REGISTRO DE ACHADOS'!$N$4:$N$1000,"BAIXA") -> 5
A8: STATUS: ABERTO | B8: =COUNTIF('REGISTRO DE ACHADOS'!$P$4:$P$1000,"ABERTO") -> 50
A9: STATUS: ENVIADO AO DESENVOLVEDOR | B9: =COUNTIF('REGISTRO DE ACHADOS'!$P$4:$P$1000,"ENVIADO AO DESENVOLVEDOR") -> 1
A10: STATUS: EM CORREÇÃO | B10: =COUNTIF('REGISTRO DE ACHADOS'!$P$4:$P$1000,"EM CORREÇÃO") -> 0
A11: STATUS: CORRIGIDO - AGUARDANDO RETESTE | B11: =COUNTIF('REGISTRO DE ACHADOS'!$P$4:$P$1000,"CORRIGIDO - AGUARDANDO RETESTE") -> 0
A12: STATUS: VALIDADO | B12: =COUNTIF('REGISTRO DE ACHADOS'!$P$4:$P$1000,"VALIDADO") -> 0
A13: STATUS: NÃO PROCEDE | B13: =COUNTIF('REGISTRO DE ACHADOS'!$P$4:$P$1000,"NÃO PROCEDE") -> 0
A14: CATEGORIA: LEITURA DO FÓLIO | B14: =COUNTIF('REGISTRO DE ACHADOS'!$G$4:$G$1000,"LEITURA DO FÓLIO") -> 24
A15: CATEGORIA: LEITURA DO TÍTULO / DOCUMENTOS | B15: =COUNTIF('REGISTRO DE ACHADOS'!$G$4:$G$1000,"LEITURA DO TÍTULO / DOCUMENTOS") -> 3
A16: CATEGORIA: NATUREZA DO ATO (LNA) | B16: =COUNTIF('REGISTRO DE ACHADOS'!$G$4:$G$1000,"NATUREZA DO ATO (LNA)") -> 6
A17: CATEGORIA: EXAME / EXIGÊNCIAS | B17: =COUNTIF('REGISTRO DE ACHADOS'!$G$4:$G$1000,"EXAME / EXIGÊNCIAS") -> 6
A18: CATEGORIA: NOTA DE EXIGÊNCIA | B18: =COUNTIF('REGISTRO DE ACHADOS'!$G$4:$G$1000,"NOTA DE EXIGÊNCIA") -> 2
A19: CATEGORIA: INTERFACE / USABILIDADE | B19: =COUNTIF('REGISTRO DE ACHADOS'!$G$4:$G$1000,"INTERFACE / USABILIDADE") -> 10
A20: TIPO: ERRO DE LEITURA | B20: =COUNTIF('REGISTRO DE ACHADOS'!$H$4:$H$1000,"ERRO DE LEITURA") -> 15
A21: TIPO: ERRO DE CLASSIFICAÇÃO | B21: =COUNTIF('REGISTRO DE ACHADOS'!$H$4:$H$1000,"ERRO DE CLASSIFICAÇÃO") -> 14
A22: TIPO: FALSO POSITIVO (EXIGÊNCIA INDEVIDA) | B22: =COUNTIF('REGISTRO DE ACHADOS'!$H$4:$H$1000,"FALSO POSITIVO (EXIGÊNCIA INDEVIDA)") -> 5
A23: TIPO: FALSO NEGATIVO (ÓBICE NÃO APONTADO) | B23: =COUNTIF('REGISTRO DE ACHADOS'!$H$4:$H$1000,"FALSO NEGATIVO (ÓBICE NÃO APONTADO)") -> 0
A24: TIPO: NÃO CONFORMIDADE NORMATIVA | B24: =COUNTIF('REGISTRO DE ACHADOS'!$H$4:$H$1000,"NÃO CONFORMIDADE NORMATIVA") -> 3
A25: TIPO: INCONSISTÊNCIA DE INTERFACE | B25: =COUNTIF('REGISTRO DE ACHADOS'!$H$4:$H$1000,"INCONSISTÊNCIA DE INTERFACE") -> 6
A26: TIPO: DÚVIDA OPERACIONAL | B26: =COUNTIF('REGISTRO DE ACHADOS'!$H$4:$H$1000,"DÚVIDA OPERACIONAL") -> 3
A27: TIPO: SUGESTÃO DE MELHORIA | B27: =COUNTIF('REGISTRO DE ACHADOS'!$H$4:$H$1000,"SUGESTÃO DE MELHORIA") -> 5
A28: ACHADOS PENDENTES DE VALIDAÇÃO (REVISÃO COMPLEMENTAR) | B28: =COUNTIF('REGISTRO DE ACHADOS'!$E$4:$E$1000,"*PENDENTE*") -> 1 | C28: Confirmar antes do envio
A29: CHECKLIST ITN 004 - ATENDE | B29: =COUNTIF('CHECKLIST ITN 004'!$F$4:$F$297,"ATENDE") -> 2
A30: CHECKLIST ITN 004 - ATENDE PARCIALMENTE | B30: =COUNTIF('CHECKLIST ITN 004'!$F$4:$F$297,"ATENDE PARCIALMENTE") -> 13
A31: CHECKLIST ITN 004 - NÃO ATENDE | B31: =COUNTIF('CHECKLIST ITN 004'!$F$4:$F$297,"NÃO ATENDE") -> 44
A32: CHECKLIST ITN 004 - VERIFICAR | B32: =COUNTIF('CHECKLIST ITN 004'!$F$4:$F$297,"VERIFICAR") -> 2
A33: CHECKLIST ITN 004 - NÃO VERIFICADO | B33: =COUNTIF('CHECKLIST ITN 004'!$F$4:$F$297,"NÃO VERIFICADO") -> 10
A34: CHECKLIST INTERFACE - ATENDE | B34: =COUNTIF('CHECKLIST INTERFACE'!$E$4:$E$300,"ATENDE") -> 2
A35: CHECKLIST INTERFACE - ATENDE PARCIALMENTE | B35: =COUNTIF('CHECKLIST INTERFACE'!$E$4:$E$300,"ATENDE PARCIALMENTE") -> 7
A36: CHECKLIST INTERFACE - NÃO ATENDE | B36: =COUNTIF('CHECKLIST INTERFACE'!$E$4:$E$300,"NÃO ATENDE") -> 15
A37: CHECKLIST INTERFACE - VERIFICAR | B37: =COUNTIF('CHECKLIST INTERFACE'!$E$4:$E$300,"VERIFICAR") -> 0
